<robot name="finger">

  <link name="metacarpals">
    <visual>
      <origin xyz="0 0 0.25" rpy="0 0 0" />
      <geometry>
        <cylinder radius="0.01" length=".5" />
      </geometry>
      <material name="red">
        <color rgba="1 0 0 1" />
      </material>
    </visual>

    <collision>
      <origin xyz="0 0 0" rpy="1.57 0 0" />
      <geometry>
        <cylinder radius="0.01" length=".5" />
      </geometry>
      <contact_coefficients mu="0" kp="1000.0" kd="1.0"/>
    </collision>
  </link>
  
  <link name="fake_proximal">
    <visual>
      <origin xyz="0 0 0.25" rpy="0 0 0" />
      <geometry>
        <cylinder radius="0.01" length=".5" />
      </geometry>
      <material name="blue">
        <color rgba="0 0 1 1" />
      </material>
    </visual>

    <collision>
      <origin xyz="0 0 0" rpy="1.57 0 0" />
      <geometry>
        <cylinder radius="0.01" length=".5" />
      </geometry>
      <contact_coefficients mu="0" kp="1000.0" kd="1.0"/>
    </collision>
  </link>
  
  <link name="proximal">
    <visual>
      <origin xyz="0 0 0.25" rpy="0 0 0" />
      <geometry>
        <cylinder radius="0.01" length=".5" />
      </geometry>
      <material name="red">
        <color rgba="1 0 0 1" />
      </material>
    </visual>

    <collision>
      <origin xyz="0 0 0" rpy="1.57 0 0" />
      <geometry>
        <cylinder radius="0.01" length=".5" />
      </geometry>
      <contact_coefficients mu="0" kp="1000.0" kd="1.0"/>
    </collision>
  </link>
  
  <link name="intermediate">
    <visual>
      <origin xyz="0 0 0.25" rpy="0 0 0" />
      <geometry>
        <cylinder radius="0.01" length=".5" />
      </geometry>
      <material name="green">
        <color rgba="0 1 0 1" />
      </material>
    </visual>

    <collision>
      <origin xyz="0 0 0" rpy="1.57 0 0" />
      <geometry>
        <cylinder radius="0.01" length=".5" />
      </geometry>
      <contact_coefficients mu="0" kp="1000.0" kd="1.0"/>
    </collision>
  </link>
  
  <link name="distal">
    <visual>
      <origin xyz="0 0 0.25" rpy="0 0 0" />
      <geometry>
        <cylinder radius="0.01" length=".5" />
      </geometry>
      <material name="blue">
        <color rgba="0 0 1 1" />
      </material>
    </visual>

    <collision>
      <origin xyz="0 0 0" rpy="1.57 0 0" />
      <geometry>
        <cylinder radius="0.01" length=".5" />
      </geometry>
      <contact_coefficients mu="0" kp="1000.0" kd="1.0"/>
    </collision>
  </link>
  
  <joint name="metacarpals_joint" type="revolute">
    <origin xyz="0 0 0.49" rpy="0 0 0"/>
    <axis xyz="0 1 0"/>
    <parent link="metacarpals"/>
    <child link="fake_proximal"/>
    <limit upper="0" lower="-.5" effort="10" velocity="10"/>
  </joint>
  
  <joint name="fake_proximal_joint" type="revolute">
    <origin xyz="0 0 0.99" rpy="0 0 0"/>
    <axis xyz="1 0 0"/>
    <parent link="fake_proximal"/>
    <child link="proximal"/>
    <limit upper="0" lower="-.5" effort="10" velocity="10"/>
  </joint>
  
  <joint name="proximal_joint" type="revolute">
    <origin xyz="0 0 1.49" rpy="0 0 0"/>
    <axis xyz="0 1 0"/>
    <parent link="proximal"/>
    <child link="intermediate"/>
    <limit upper="0" lower="-.5" effort="10" velocity="10"/>
  </joint>
  
  <joint name="intermediate_joint" type="revolute">
    <origin xyz="0 0 1.99" rpy="0 0 0"/>
    <axis xyz="0 1 0"/>
    <parent link="intermediate"/>
    <child link="distal"/>
    <limit upper="0" lower="-.5" effort="10" velocity="10"/>
  </joint>

</robot>
